<?xml version="1.0" ?>
<!-- =================================================================================== -->
<!-- |    This document was autogenerated by xacro from /home/axellkir/test_ws/src/husky/husky_description/urdf/husky.urdf.xacro | -->
<!-- |    EDITING THIS FILE BY HAND IS NOT RECOMMENDED                                 | -->
<!-- =================================================================================== -->
<!--
Software License Agreement (BSD)

\file      husky.urdf.xacro
\authors   Paul Bovbel <pbovbel@clearpathrobotics.com>, Devon Ash <dash@clearpathrobotics.com>
\copyright Copyright (c) 2015, Clearpath Robotics, Inc., All rights reserved.

Redistribution and use in source and binary forms, with or without modification, are permitted provided that
the following conditions are met:
 * Redistributions of source code must retain the above copyright notice, this list of conditions and the
   following disclaimer.
 * Redistributions in binary form must reproduce the above copyright notice, this list of conditions and the
   following disclaimer in the documentation and/or other materials provided with the distribution.
 * Neither the name of Clearpath Robotics nor the names of its contributors may be used to endorse or promote
   products derived from this software without specific prior written permission.

THIS SOFTWARE IS PROVIDED BY THE COPYRIGHT HOLDERS AND CONTRIBUTORS "AS IS" AND ANY EXPRESS OR IMPLIED WAR-
RANTIES, INCLUDING, BUT NOT LIMITED TO, THE IMPLIED WARRANTIES OF MERCHANTABILITY AND FITNESS FOR A PARTICULAR
PURPOSE ARE DISCLAIMED. IN NO EVENT SHALL THE COPYRIGHT HOLDER OR CONTRIBUTORS BE LIABLE FOR ANY DIRECT, IN-
DIRECT, INCIDENTAL, SPECIAL, EXEMPLARY, OR CONSEQUENTIAL DAMAGES (INCLUDING, BUT NOT LIMITED TO, PROCUREMENT
OF SUBSTITUTE GOODS OR SERVICES; LOSS OF USE, DATA, OR PROFITS; OR BUSINESS INTERRUPTION) HOWEVER CAUSED AND
ON ANY THEORY OF LIABILITY, WHETHER IN CONTRACT, STRICT LIABILITY, OR TORT (INCLUDING NEGLIGENCE OR OTHERWISE)
ARISING IN ANY WAY OUT OF THE USE OF THIS SOFTWARE, EVEN IF ADVISED OF THE POSSIBILITY OF SUCH DAMAGE.
-->
<robot name="husky">
    <material name="dark_grey">
        <color rgba="0.2 0.2 0.2 1.0" />
    </material>
    <material name="medium_grey">
        <color rgba="0.6 0.6 0.6 1.0" />
    </material>
    <material name="light_grey">
        <color rgba="0.8 0.8 0.8 1.0" />
    </material>
    <material name="yellow">
        <color rgba="0.8 0.8 0.0 1.0" />
    </material>
    <material name="black">
        <color rgba="0.15 0.15 0.15 1.0" />
    </material>
    <material name="white">
        <color rgba="1.0 1.0 1.0 1.0" />
    </material>
    <material name="red">
        <color rgba="1.0 0.0 0.0 1.0" />
    </material>
    <gazebo>
        <plugin filename="libgazebo_ros_control.so" name="ros_control">
            <!--robotNamespace>/</robotNamespace-->
            <!--robotSimType>gazebo_ros_control/DefaultRobotHWSim</robotSimType-->
        </plugin>
        <!--
    <plugin name="gazebo_ros_power_monitor_controller" filename="libgazebo_ros_power_monitor.so">
      <alwaysOn>true</alwaysOn>
      <updateRate>1.0</updateRate>
      <timeout>5</timeout>
      <powerStateTopic>power_state</powerStateTopic>
      <powerStateRate>10.0</powerStateRate>
      <fullChargeCapacity>87.78</fullChargeCapacity>     
      <dischargeRate>-474</dischargeRate>
      <chargeRate>525</chargeRate>
      <dischargeVoltage>15.52</dischargeVoltage>
      <chargeVoltage>16.41</chargeVoltage>
    </plugin>
-->
    </gazebo>
    <joint name="arm_mount_joint" type="fixed">
        <parent link="top_plate_front_link" />
        <child link="ur_arm_base_link" />
        <origin rpy="0 0 3.1415927" xyz="-0.105 0.0 0.0" />
    </joint>
    <!-- measured from model -->
    <!--property name="shoulder_height" value="0.089159" /-->
    <!--property name="shoulder_offset" value="0.13585" /-->
    <!-- shoulder_offset - elbow_offset + wrist_1_length = 0.10915 -->
    <!--property name="upper_arm_length" value="0.42500" /-->
    <!--property name="elbow_offset" value="0.1197" /-->
    <!-- CAD measured -->
    <!--property name="forearm_length" value="0.39225" /-->
    <!--property name="wrist_1_length" value="0.093" /-->
    <!-- CAD measured -->
    <!--property name="wrist_2_length" value="0.09465" /-->
    <!-- In CAD this distance is 0.930, but in the spec it is 0.09465 -->
    <!--property name="wrist_3_length" value="0.0823" /-->
    <!-- manually measured -->
    <link name="ur_arm_base_link">
        <visual>
            <geometry>
                <mesh filename="./meshes/ur5/visual/base.dae" />
            </geometry>
            <material name="LightGrey">
                <color rgba="0.7 0.7 0.7 1.0" />
            </material>
        </visual>
        <collision>
            <geometry>
                <mesh filename="./meshes/ur5/collision/base.stl" />
            </geometry>
        </collision>
        
<inertial>
            <mass value="4.0" />
            <origin rpy="0 0 0" xyz="0.0 0.0 0.0" />
            <inertia ixx="0.00443333156" ixy="0.0" ixz="0.0" iyy="0.00443333156" iyz="0.0" izz="0.0072" />
        </inertial>

    </link>
    <joint name="ur_arm_shoulder_pan_joint" type="revolute">
        <parent link="ur_arm_base_link" />
        <child link="ur_arm_shoulder_link" />
        <origin rpy="0.0 0.0 0.0" xyz="0.0 0.0 0.089159" />
        <axis xyz="0 0 1" />
        <limit effort="150.0" lower="-3.141592653589793" upper="3.141592653589793" velocity="3.15" />
        <dynamics damping="0.0" friction="0.0" />
    </joint>
    <link name="ur_arm_shoulder_link">
        <visual>
            <geometry>
                <mesh filename="./meshes/ur5/visual/shoulder.dae" />
            </geometry>
            <material name="LightGrey">
                <color rgba="0.7 0.7 0.7 1.0" />
            </material>
        </visual>
        <collision>
            <geometry>
                <mesh filename="./meshes/ur5/collision/shoulder.stl" />
            </geometry>
        </collision>
        
<inertial>
            <mass value="3.7" />
            <origin rpy="0 0 0" xyz="0.0 0.0 0.0" />
            <inertia ixx="0.010267495893" ixy="0.0" ixz="0.0" iyy="0.010267495893" iyz="0.0" izz="0.00666" />
        </inertial>

    </link>
    <joint name="ur_arm_shoulder_lift_joint" type="revolute">
        <parent link="ur_arm_shoulder_link" />
        <child link="ur_arm_upper_arm_link" />
        <origin rpy="0.0 1.5707963267948966 0.0" xyz="0.0 0.13585 0.0" />
        <axis xyz="0 1 0" />
        <limit effort="150.0" lower="-3.141592653589793" upper="3.141592653589793" velocity="3.15" />
        <dynamics damping="0.0" friction="0.0" />
    </joint>
    <link name="ur_arm_upper_arm_link">
        <visual>
            <geometry>
                <mesh filename="./meshes/ur5/visual/upperarm.dae" />
            </geometry>
            <material name="LightGrey">
                <color rgba="0.7 0.7 0.7 1.0" />
            </material>
        </visual>
        <collision>
            <geometry>
                <mesh filename="./meshes/ur5/collision/upperarm.stl" />
            </geometry>
        </collision>
        
<inertial>
            <mass value="8.393" />
            <origin rpy="0 0 0" xyz="0.0 0.0 0.28" />
            <inertia ixx="0.22689067591036005" ixy="0.0" ixz="0.0" iyy="0.22689067591036005" iyz="0.0" izz="0.0151074" />
        </inertial>

    </link>
    <joint name="ur_arm_elbow_joint" type="revolute">
        <parent link="ur_arm_upper_arm_link" />
        <child link="ur_arm_forearm_link" />
        <origin rpy="0.0 0.0 0.0" xyz="0.0 -0.1197 0.425" />
        <axis xyz="0 1 0" />
        <limit effort="150.0" lower="-3.141592653589793" upper="3.141592653589793" velocity="3.15" />
        <dynamics damping="0.0" friction="0.0" />
    </joint>
    <link name="ur_arm_forearm_link">
        <visual>
            <geometry>
                <mesh filename="./meshes/ur5/visual/forearm.dae" />
            </geometry>
            <material name="LightGrey">
                <color rgba="0.7 0.7 0.7 1.0" />
            </material>
        </visual>
        <collision>
            <geometry>
                <mesh filename="./meshes/ur5/collision/forearm.stl" />
            </geometry>
        </collision>
        
<inertial>
            <mass value="2.275" />
            <origin rpy="0 0 0" xyz="0.0 0.0 0.196125" />
            <inertia ixx="0.03121679102890359" ixy="0.0" ixz="0.0" iyy="0.03121679102890359" iyz="0.0" izz="0.004095" />
        </inertial>

    </link>
    <joint name="ur_arm_wrist_1_joint" type="revolute">
        <parent link="ur_arm_forearm_link" />
        <child link="ur_arm_wrist_1_link" />
        <origin rpy="0.0 1.5707963267948966 0.0" xyz="0.0 0.0 0.39225" />
        <axis xyz="0 1 0" />
        <limit effort="28.0" lower="-3.141592653589793" upper="3.141592653589793" velocity="3.2" />
        <dynamics damping="0.0" friction="0.0" />
    </joint>
    <link name="ur_arm_wrist_1_link">
        <visual>
            <geometry>
                <mesh filename="./meshes/ur5/visual/wrist1.dae" />
            </geometry>
            <material name="LightGrey">
                <color rgba="0.7 0.7 0.7 1.0" />
            </material>
        </visual>
        <collision>
            <geometry>
                <mesh filename="./meshes/ur5/collision/wrist1.stl" />
            </geometry>
        </collision>
        
<inertial>
            <mass value="1.219" />
            <origin rpy="0 0 0" xyz="0.0 0.093 0.0" />
            <inertia ixx="0.0025598989760400002" ixy="0.0" ixz="0.0" iyy="0.0025598989760400002" iyz="0.0" izz="0.0021942" />
        </inertial>

    </link>
    <joint name="ur_arm_wrist_2_joint" type="revolute">
        <parent link="ur_arm_wrist_1_link" />
        <child link="ur_arm_wrist_2_link" />
        <origin rpy="0.0 0.0 0.0" xyz="0.0 0.093 0.0" />
        <axis xyz="0 0 1" />
        <limit effort="28.0" lower="-3.141592653589793" upper="3.141592653589793" velocity="3.2" />
        <dynamics damping="0.0" friction="0.0" />
    </joint>
    <link name="ur_arm_wrist_2_link">
        <visual>
            <geometry>
                <mesh filename="./meshes/ur5/visual/wrist2.dae" />
            </geometry>
            <material name="LightGrey">
                <color rgba="0.7 0.7 0.7 1.0" />
            </material>
        </visual>
        <collision>
            <geometry>
                <mesh filename="./meshes/ur5/collision/wrist2.stl" />
            </geometry>
        </collision>
        
<inertial>
            <mass value="1.219" />
            <origin rpy="0 0 0" xyz="0.0 0.0 0.09465" />
            <inertia ixx="0.0025598989760400002" ixy="0.0" ixz="0.0" iyy="0.0025598989760400002" iyz="0.0" izz="0.0021942" />
        </inertial>

    </link>
    <joint name="ur_arm_wrist_3_joint" type="revolute">
        <parent link="ur_arm_wrist_2_link" />
        <child link="ur_arm_wrist_3_link" />
        <origin rpy="0.0 0.0 0.0" xyz="0.0 0.0 0.09465" />
        <axis xyz="0 1 0" />
        <limit effort="28.0" lower="-3.141592653589793" upper="3.141592653589793" velocity="3.2" />
        <dynamics damping="0.0" friction="0.0" />
    </joint>
    <link name="ur_arm_wrist_3_link">
        <visual>
            <geometry>
                <mesh filename="./meshes/ur5/visual/wrist3.dae" />
            </geometry>
            <material name="LightGrey">
                <color rgba="0.7 0.7 0.7 1.0" />
            </material>
        </visual>
        <collision>
            <geometry>
                <mesh filename="./meshes/ur5/collision/wrist3.stl" />
            </geometry>
        </collision>
        
<inertial>
            <mass value="0.1879" />
            <origin rpy="1.5707963267948966 0 0" xyz="0.0 0.06505 0.0" />
            <inertia ixx="8.469589112163e-05" ixy="0.0" ixz="0.0" iyy="8.469589112163e-05" iyz="0.0" izz="0.0001321171875" />
        </inertial>

    </link>
    <joint name="robotiq_85_base_joint" type="fixed">
        <parent link="ur_arm_wrist_3_link" />
        <child link="robotiq_85_base_link" />
        <origin rpy="0 0 1.5707963267948966" xyz="0 0.0719 0" />
    </joint>
    <link name="robotiq_85_base_link">
        <visual>
            <geometry>
                <mesh filename="./meshes/robotiq/visual/robotiq_85_base_link.dae" />
            </geometry>
        </visual>
        <collision>
            <geometry>
                <mesh filename="./meshes/robotiq/collision/robotiq_85_base_link.stl" />
            </geometry>
        </collision>
        
<inertial>
            <mass value="0.636951" />
            <origin xyz="0.0 0.0 0.0" />
            <inertia ixx="0.000380" ixy="0.000000" ixz="0.000000" iyx="0.000000" iyy="0.001110" iyz="0.000000" izx="0.000000" izy="0.000000" izz="0.001171" />
        </inertial>

    </link>
    <joint name="robotiq_85_left_knuckle_joint" type="revolute">
        <parent link="robotiq_85_base_link" />
        <child link="robotiq_85_left_knuckle_link" />
        <axis xyz="0 0 1" />
        <origin rpy="3.141592653589793 0.0 0.0" xyz="0.05490451627 0.03060114443 0.0" />
        <limit effort="1000" lower="0.0" upper="0.80285" velocity="0.5" />
    </joint>
    <joint name="robotiq_85_right_knuckle_joint" type="continuous">
        <parent link="robotiq_85_base_link" />
        <child link="robotiq_85_right_knuckle_link" />
        <axis xyz="0 0 1" />
        <origin rpy="0.0 0.0 0.0" xyz="0.05490451627 -0.03060114443 0.0" />
        <limit effort="1000" lower="-3.14" upper="3.14" velocity="100.0" />
        <mimic joint="robotiq_85_left_knuckle_joint" />
    </joint>
    <link name="robotiq_85_left_knuckle_link">
        <visual>
            <geometry>
                <mesh filename="./meshes/robotiq/visual/robotiq_85_knuckle_link.dae" />
            </geometry>
        </visual>
        <collision>
            <geometry>
                <mesh filename="./meshes/robotiq/collision/robotiq_85_knuckle_link.stl" />
            </geometry>
        </collision>
        
<inertial>
            <mass value="0.018491" />
            <origin xyz="0.0 0.0 0.0" />
            <inertia ixx="0.000009" ixy="-0.000001" ixz="0.000000" iyx="-0.000001" iyy="0.000001" iyz="0.000000" izx="0.000000" izy="0.000000" izz="0.000010" />
        </inertial>

    </link>
    <link name="robotiq_85_right_knuckle_link">
        <visual>
            <geometry>
                <mesh filename="./meshes/robotiq/visual/robotiq_85_knuckle_link.dae" />
            </geometry>
        </visual>
        <collision>
            <geometry>
                <mesh filename="./meshes/robotiq/collision/robotiq_85_knuckle_link.stl" />
            </geometry>
        </collision>
        
<inertial>
            <mass value="0.018491" />
            <origin xyz="0.0 0.0 0.0" />
            <inertia ixx="0.000009" ixy="-0.000001" ixz="0.000000" iyx="-0.000001" iyy="0.000001" iyz="0.000000" izx="0.000000" izy="0.000000" izz="0.000010" />
        </inertial>

    </link>
    <joint name="robotiq_85_left_finger_joint" type="fixed">
        <parent link="robotiq_85_left_knuckle_link" />
        <child link="robotiq_85_left_finger_link" />
        <origin rpy="0 0 0" xyz="-0.00408552455 -0.03148604435 0.0" />
    </joint>
    <joint name="robotiq_85_right_finger_joint" type="fixed">
        <parent link="robotiq_85_right_knuckle_link" />
        <child link="robotiq_85_right_finger_link" />
        <origin rpy="0 0 0" xyz="-0.00408552455 -0.03148604435 0.0" />
    </joint>
    <link name="robotiq_85_left_finger_link">
        <visual>
            <geometry>
                <mesh filename="./meshes/robotiq/visual/robotiq_85_finger_link.dae" />
            </geometry>
        </visual>
        <collision>
            <geometry>
                <mesh filename="./meshes/robotiq/collision/robotiq_85_finger_link.stl" />
            </geometry>
        </collision>
        
<inertial>
            <mass value="0.027309" />
            <origin xyz="0.0 0.0 0.0" />
            <inertia ixx="0.000003" ixy="-0.000002" ixz="0.000000" iyx="-0.000002" iyy="0.000021" iyz="0.000000" izx="0.000000" izy="0.000000" izz="0.000020" />
        </inertial>

    </link>
    <link name="robotiq_85_right_finger_link">
        <visual>
            <geometry>
                <mesh filename="./meshes/robotiq/visual/robotiq_85_finger_link.dae" />
            </geometry>
        </visual>
        <collision>
            <geometry>
                <mesh filename="./meshes/robotiq/collision/robotiq_85_finger_link.stl" />
            </geometry>
        </collision>
        
<inertial>
            <mass value="0.027309" />
            <origin xyz="0.0 0.0 0.0" />
            <inertia ixx="0.000003" ixy="-0.000002" ixz="0.000000" iyx="-0.000002" iyy="0.000021" iyz="0.000000" izx="0.000000" izy="0.000000" izz="0.000020" />
        </inertial>

    </link>
    <joint name="robotiq_85_left_inner_knuckle_joint" type="continuous">
        <parent link="robotiq_85_base_link" />
        <child link="robotiq_85_left_inner_knuckle_link" />
        <axis xyz="0 0 1" />
        <origin rpy="3.141592653589793 0.0 0.0" xyz="0.06142 0.0127 0" />
        <limit effort="0.1" lower="-3.14" upper="3.14" velocity="100.0" />
        <mimic joint="robotiq_85_left_knuckle_joint" offset="0" />
    </joint>
    <joint name="robotiq_85_right_inner_knuckle_joint" type="continuous">
        <parent link="robotiq_85_base_link" />
        <child link="robotiq_85_right_inner_knuckle_link" />
        <axis xyz="0 0 1" />
        <origin rpy="0 0 0" xyz="0.06142 -0.0127 0" />
        <limit effort="0.1" lower="-3.14" upper="3.14" velocity="100.0" />
        <mimic joint="robotiq_85_left_knuckle_joint" offset="0" />
    </joint>
    <link name="robotiq_85_left_inner_knuckle_link">
        <visual>
            <geometry>
                <mesh filename="./meshes/robotiq/visual/robotiq_85_inner_knuckle_link.dae" />
            </geometry>
        </visual>
        <collision>
            <geometry>
                <mesh filename="./meshes/robotiq/collision/robotiq_85_inner_knuckle_link.stl" />
            </geometry>
        </collision>
        
<inertial>
            <mass value="0.029951" />
            <origin xyz="0.0 0.0 0.0" />
            <inertia ixx="0.000039" ixy="0.000000" ixz="0.000000" iyx="0.000000" iyy="0.000005" iyz="0.000000" izx="0.000000" izy="0.000000" izz="0.000035" />
        </inertial>

    </link>
    <link name="robotiq_85_right_inner_knuckle_link">
        <visual>
            <geometry>
                <mesh filename="./meshes/robotiq/visual/robotiq_85_inner_knuckle_link.dae" />
            </geometry>
        </visual>
        <collision>
            <geometry>
                <mesh filename="./meshes/robotiq/collision/robotiq_85_inner_knuckle_link.stl" />
            </geometry>
        </collision>
        
<inertial>
            <mass value="0.029951" />
            <origin xyz="0.0 0.0 0.0" />
            <inertia ixx="0.000039" ixy="0.000000" ixz="0.000000" iyx="0.000000" iyy="0.000005" iyz="0.000000" izx="0.000000" izy="0.000000" izz="0.000035" />
        </inertial>

    </link>
    <joint name="robotiq_85_left_finger_tip_joint" type="continuous">
        <parent link="robotiq_85_left_inner_knuckle_link" />
        <child link="robotiq_85_left_finger_tip_link" />
        <axis xyz="0 0 1" />
        <origin rpy="0.0 0.0 0.0" xyz="0.04303959807 -0.03759940821 0.0" />
        <limit effort="0.1" lower="-3.14" upper="3.14" velocity="100.0" />
        <mimic joint="robotiq_85_left_knuckle_joint" multiplier="-1" />
    </joint>
    <joint name="robotiq_85_right_finger_tip_joint" type="continuous">
        <parent link="robotiq_85_right_inner_knuckle_link" />
        <child link="robotiq_85_right_finger_tip_link" />
        <axis xyz="0 0 1" />
        <origin rpy="0.0 0.0 0.0" xyz="0.04303959807 -0.03759940821  0.0" />
        <limit effort="0.1" lower="-3.14" upper="3.14" velocity="100.0" />
        <mimic joint="robotiq_85_left_knuckle_joint" multiplier="-1" />
    </joint>
    <link name="robotiq_85_left_finger_tip_link">
        <visual>
            <geometry>
                <mesh filename="./meshes/robotiq/visual/robotiq_85_finger_tip_link.dae" />
            </geometry>
        </visual>
        <collision>
            <geometry>
                <mesh filename="./meshes/robotiq/collision/robotiq_85_finger_tip_link.stl" />
            </geometry>
        </collision>
        
<inertial>
            <mass value="0.019555" />
            <origin xyz="0.0 0.0 0.0" />
            <inertia ixx="0.000002" ixy="0.000000" ixz="0.000000" iyx="0.000000" iyy="0.000005" iyz="0.000000" izx="0.000000" izy="0.000000" izz="0.000006" />
        </inertial>

    </link>
    <link name="robotiq_85_right_finger_tip_link">
        <visual>
            <geometry>
                <mesh filename="./meshes/robotiq/visual/robotiq_85_finger_tip_link.dae" />
            </geometry>
        </visual>
        <collision>
            <geometry>
                <mesh filename="./meshes/robotiq/collision/robotiq_85_finger_tip_link.stl" />
            </geometry>
        </collision>
        
<inertial>
            <mass value="0.019555" />
            <origin xyz="0.0 0.0 0.0" />
            <inertia ixx="0.000002" ixy="0.000000" ixz="0.000000" iyx="0.000000" iyy="0.000005" iyz="0.000000" izx="0.000000" izy="0.000000" izz="0.000006" />
        </inertial>

    </link>
    <!-- Improve grasping physics -->
    <gazebo reference="robotiq_85_left_finger_tip_link">
        <kp>1000000.0</kp>
        <kd>1.0</kd>
        <mu1>1.0</mu1>
        <mu2>1.0</mu2>
        <minDepth>0.001</minDepth>
    </gazebo>
    <gazebo reference="robotiq_85_right_finger_tip_link">
        <kp>1000000.0</kp>
        <kd>1.0</kd>
        <mu1>1.0</mu1>
        <mu2>1.0</mu2>
        <minDepth>0.001</minDepth>
    </gazebo>
    <transmission name="robotiq_85_left_knuckle_trans">
        <type>transmission_interface/SimpleTransmission</type>
        <joint name="robotiq_85_left_knuckle_joint">
            <hardwareInterface>PositionJointInterface</hardwareInterface>
            <!-- <hardwareInterface>EffortJointInterface</hardwareInterface> -->
        </joint>
        <actuator name="robotiq_85_left_knuckle_motor">
            <mechanicalReduction>1</mechanicalReduction>
            <hardwareInterface>PositionJointInterface</hardwareInterface>
            <!-- <hardwareInterface>EfforJointInterface</hardwareInterface> -->
        </actuator>
    </transmission>
    <!-- Mimic joints -->
    <gazebo>
        <plugin filename="libgazebo_mimic_joint_plugin.so" name="mimic_robotiq_85_1">
            <joint>robotiq_85_left_knuckle_joint</joint>
            <mimicJoint>robotiq_85_right_knuckle_joint</mimicJoint>
        </plugin>
        <plugin filename="libgazebo_mimic_joint_plugin.so" name="mimic_robotiq_85_2">
            <joint>robotiq_85_left_knuckle_joint</joint>
            <mimicJoint>robotiq_85_left_inner_knuckle_joint</mimicJoint>
        </plugin>
        <plugin filename="libgazebo_mimic_joint_plugin.so" name="mimic_robotiq_85_3">
            <joint>robotiq_85_left_knuckle_joint</joint>
            <mimicJoint>robotiq_85_right_inner_knuckle_joint</mimicJoint>
        </plugin>
        <plugin filename="libgazebo_mimic_joint_plugin.so" name="mimic_robotiq_85_4">
            <joint>robotiq_85_left_knuckle_joint</joint>
            <mimicJoint>robotiq_85_left_finger_tip_joint</mimicJoint>
            <multiplier>-1.0</multiplier>
            <offset>0.0</offset>
        </plugin>
        <plugin filename="libgazebo_mimic_joint_plugin.so" name="mimic_robotiq_85_5">
            <joint>robotiq_85_left_knuckle_joint</joint>
            <mimicJoint>robotiq_85_right_finger_tip_joint</mimicJoint>
            <multiplier>-1.0</multiplier>
            <offset>0.0</offset>
        </plugin>
    </gazebo>
    <joint name="ur_arm_ee_fixed_joint" type="fixed">
        <parent link="ur_arm_wrist_3_link" />
        <child link="ur_arm_ee_link" />
        <origin rpy="0.0 0.0 1.5707963267948966" xyz="0.0 0.0823 0.0" />
    </joint>
    <link name="ur_arm_ee_link">
        <collision>
            <geometry>
                <box size="0.01 0.01 0.01" />
            </geometry>
            <origin rpy="0 0 0" xyz="-0.01 0 0" />
        </collision>
        
<inertial>
            <mass value="0.1" />
            <inertia ixx="0.03" iyy="0.03" izz="0.03" ixy="0.0" ixz="0.0" iyz="0.0" />
        </inertial>

    </link>
    <transmission name="ur_arm_shoulder_pan_trans">
        <type>transmission_interface/SimpleTransmission</type>
        <joint name="ur_arm_shoulder_pan_joint">
            <hardwareInterface>hardware_interface/PositionJointInterface</hardwareInterface>
        </joint>
        <actuator name="ur_arm_shoulder_pan_motor">
            <mechanicalReduction>1</mechanicalReduction>
        </actuator>
    </transmission>
    <transmission name="ur_arm_shoulder_lift_trans">
        <type>transmission_interface/SimpleTransmission</type>
        <joint name="ur_arm_shoulder_lift_joint">
            <hardwareInterface>hardware_interface/PositionJointInterface</hardwareInterface>
        </joint>
        <actuator name="ur_arm_shoulder_lift_motor">
            <mechanicalReduction>1</mechanicalReduction>
        </actuator>
    </transmission>
    <transmission name="ur_arm_elbow_trans">
        <type>transmission_interface/SimpleTransmission</type>
        <joint name="ur_arm_elbow_joint">
            <hardwareInterface>hardware_interface/PositionJointInterface</hardwareInterface>
        </joint>
        <actuator name="ur_arm_elbow_motor">
            <mechanicalReduction>1</mechanicalReduction>
        </actuator>
    </transmission>
    <transmission name="ur_arm_wrist_1_trans">
        <type>transmission_interface/SimpleTransmission</type>
        <joint name="ur_arm_wrist_1_joint">
            <hardwareInterface>hardware_interface/PositionJointInterface</hardwareInterface>
        </joint>
        <actuator name="ur_arm_wrist_1_motor">
            <mechanicalReduction>1</mechanicalReduction>
        </actuator>
    </transmission>
    <transmission name="ur_arm_wrist_2_trans">
        <type>transmission_interface/SimpleTransmission</type>
        <joint name="ur_arm_wrist_2_joint">
            <hardwareInterface>hardware_interface/PositionJointInterface</hardwareInterface>
        </joint>
        <actuator name="ur_arm_wrist_2_motor">
            <mechanicalReduction>1</mechanicalReduction>
        </actuator>
    </transmission>
    <transmission name="ur_arm_wrist_3_trans">
        <type>transmission_interface/SimpleTransmission</type>
        <joint name="ur_arm_wrist_3_joint">
            <hardwareInterface>hardware_interface/PositionJointInterface</hardwareInterface>
        </joint>
        <actuator name="ur_arm_wrist_3_motor">
            <mechanicalReduction>1</mechanicalReduction>
        </actuator>
    </transmission>
    <gazebo reference="ur_arm_shoulder_link">
        <selfCollide>true</selfCollide>
    </gazebo>
    <gazebo reference="ur_arm_upper_arm_link">
        <selfCollide>true</selfCollide>
    </gazebo>
    <gazebo reference="ur_arm_forearm_link">
        <selfCollide>true</selfCollide>
    </gazebo>
    <gazebo reference="ur_arm_wrist_1_link">
        <selfCollide>true</selfCollide>
    </gazebo>
    <gazebo reference="ur_arm_wrist_3_link">
        <selfCollide>true</selfCollide>
    </gazebo>
    <gazebo reference="ur_arm_wrist_2_link">
        <selfCollide>true</selfCollide>
    </gazebo>
    <gazebo reference="ur_arm_ee_link">
        <selfCollide>true</selfCollide>
    </gazebo>
    <!-- ROS base_link to UR 'Base' Coordinates transform -->
    <link name="ur_arm_base" />
    <joint name="ur_arm_base_link-base_fixed_joint" type="fixed">
        <!-- NOTE: this rotation is only needed as long as base_link itself is
                 not corrected wrt the real robot (ie: rotated over 180
                 degrees)
      -->
        <origin rpy="0 0 -3.141592653589793" xyz="0 0 0" />
        <parent link="ur_arm_base_link" />
        <child link="ur_arm_base" />
    </joint>
    <!-- Frame coincident with all-zeros TCP on UR controller -->
    <link name="ur_arm_tool0" />
    <joint name="ur_arm_wrist_3_link-tool0_fixed_joint" type="fixed">
        <origin rpy="-1.5707963267948966 0 0" xyz="0 0.0823 0" />
        <parent link="ur_arm_wrist_3_link" />
        <child link="ur_arm_tool0" />
    </joint>
    <!-- kinematics_file="${load_yaml('$(arg kinematics_config)')}" -->
    <!-- Base link is the center of the robot's bottom plate -->
    <link name="base_link">
        <visual>
            <origin rpy="0 0 0" xyz="0 0 0" />
            <geometry>
                <mesh filename="./meshes/husky/base_link.dae" />
            </geometry>
        </visual>
        <collision>
            <origin rpy="0 0 0" xyz="0.0 0 0.061875" />
            <geometry>
                <box size="0.9874 0.5709 0.12375" />
            </geometry>
        </collision>
        <collision>
            <origin rpy="0 0 0" xyz="0 0 0.17562499999999998" />
            <geometry>
                <box size="0.7899200000000001 0.5709 0.10375" />
            </geometry>
        </collision>
        
<inertial>
            <mass value="0.1" />
            <inertia ixx="0.03" iyy="0.03" izz="0.03" ixy="0.0" ixz="0.0" iyz="0.0" />
        </inertial>

    </link>
    <!-- Base footprint is on the ground under the robot -->
    <link name="base_footprint" />
    <joint name="base_footprint_joint" type="fixed">
        <origin rpy="0 0 0" xyz="0 0 -0.13228" />
        <parent link="base_link" />
        <child link="base_footprint" />
    </joint>
    <!-- Inertial link stores the robot's inertial information -->
    <link name="inertial_link">
        
<inertial>
            <mass value="46.034" />
            <origin xyz="-0.00065 -0.085 0.062" />
            <inertia ixx="0.6022" ixy="-0.02364" ixz="-0.1197" iyy="1.7386" iyz="-0.001544" izz="2.0296" />
        </inertial>

    </link>
    <joint name="inertial_joint" type="fixed">
        <origin rpy="0 0 0" xyz="0 0 0" />
        <parent link="base_link" />
        <child link="inertial_link" />
    </joint>
    <!-- IMU Link is the standard mounting position for the UM6 IMU.-->
    <!-- Can be modified with environment variables in /etc/ros/setup.bash -->
    <link name="imu_link" />
    <joint name="imu_joint" type="fixed">
        <origin rpy="0 -1.5708 3.1416" xyz="0.19 0 0.149" />
        <parent link="base_link" />
        <child link="imu_link" />
    </joint>
    <gazebo reference="imu_link" />
    <link name="front_left_wheel_link">
        
<inertial>
            <mass value="2.637" />
            <origin xyz="0 0 0" />
            <inertia ixx="0.02467" ixy="0" ixz="0" iyy="0.04411" iyz="0" izz="0.02467" />
        </inertial>

        <visual>
            <origin rpy="0 0 0" xyz="0 0 0" />
            <geometry>
                <mesh filename="./meshes/husky/wheel.dae" />
            </geometry>
        </visual>
        <collision>
            <origin rpy="1.570795 0 0" xyz="0 0 0" />
            <geometry>
                <cylinder length="0.1143" radius="0.1651" />
            </geometry>
        </collision>
    </link>
    <gazebo reference="front_left_wheel_link">
        <mu1 value="1.0" />
        <mu2 value="1.0" />
        <kp value="10000000.0" />
        <kd value="1.0" />
        <fdir1 value="1 0 0" />
    </gazebo>
    <joint name="front_left_wheel" type="continuous">
        <parent link="base_link" />
        <child link="front_left_wheel_link" />
        <origin rpy="0 0 0" xyz="0.256 0.2854 0.03282" />
        <axis rpy="0 0 0" xyz="0 1 0" />
    </joint>
    <transmission name="front_left_wheel_trans" type="SimpleTransmission">
        <type>transmission_interface/SimpleTransmission</type>
        <actuator name="front_left_wheel_motor">
            <mechanicalReduction>1</mechanicalReduction>
        </actuator>
        <joint name="front_left_wheel">
            <hardwareInterface>hardware_interface/VelocityJointInterface</hardwareInterface>
        </joint>
    </transmission>
    <link name="front_right_wheel_link">
        
<inertial>
            <mass value="2.637" />
            <origin xyz="0 0 0" />
            <inertia ixx="0.02467" ixy="0" ixz="0" iyy="0.04411" iyz="0" izz="0.02467" />
        </inertial>

        <visual>
            <origin rpy="0 0 0" xyz="0 0 0" />
            <geometry>
                <mesh filename="./meshes/husky/wheel.dae" />
            </geometry>
        </visual>
        <collision>
            <origin rpy="1.570795 0 0" xyz="0 0 0" />
            <geometry>
                <cylinder length="0.1143" radius="0.1651" />
            </geometry>
        </collision>
    </link>
    <gazebo reference="front_right_wheel_link">
        <mu1 value="1.0" />
        <mu2 value="1.0" />
        <kp value="10000000.0" />
        <kd value="1.0" />
        <fdir1 value="1 0 0" />
    </gazebo>
    <joint name="front_right_wheel" type="continuous">
        <parent link="base_link" />
        <child link="front_right_wheel_link" />
        <origin rpy="0 0 0" xyz="0.256 -0.2854 0.03282" />
        <axis rpy="0 0 0" xyz="0 1 0" />
    </joint>
    <transmission name="front_right_wheel_trans" type="SimpleTransmission">
        <type>transmission_interface/SimpleTransmission</type>
        <actuator name="front_right_wheel_motor">
            <mechanicalReduction>1</mechanicalReduction>
        </actuator>
        <joint name="front_right_wheel">
            <hardwareInterface>hardware_interface/VelocityJointInterface</hardwareInterface>
        </joint>
    </transmission>
    <link name="rear_left_wheel_link">
        
<inertial>
            <mass value="2.637" />
            <origin xyz="0 0 0" />
            <inertia ixx="0.02467" ixy="0" ixz="0" iyy="0.04411" iyz="0" izz="0.02467" />
        </inertial>

        <visual>
            <origin rpy="0 0 0" xyz="0 0 0" />
            <geometry>
                <mesh filename="./meshes/husky/wheel.dae" />
            </geometry>
        </visual>
        <collision>
            <origin rpy="1.570795 0 0" xyz="0 0 0" />
            <geometry>
                <cylinder length="0.1143" radius="0.1651" />
            </geometry>
        </collision>
    </link>
    <gazebo reference="rear_left_wheel_link">
        <mu1 value="1.0" />
        <mu2 value="1.0" />
        <kp value="10000000.0" />
        <kd value="1.0" />
        <fdir1 value="1 0 0" />
    </gazebo>
    <joint name="rear_left_wheel" type="continuous">
        <parent link="base_link" />
        <child link="rear_left_wheel_link" />
        <origin rpy="0 0 0" xyz="-0.256 0.2854 0.03282" />
        <axis rpy="0 0 0" xyz="0 1 0" />
    </joint>
    <transmission name="rear_left_wheel_trans" type="SimpleTransmission">
        <type>transmission_interface/SimpleTransmission</type>
        <actuator name="rear_left_wheel_motor">
            <mechanicalReduction>1</mechanicalReduction>
        </actuator>
        <joint name="rear_left_wheel">
            <hardwareInterface>hardware_interface/VelocityJointInterface</hardwareInterface>
        </joint>
    </transmission>
    <link name="rear_right_wheel_link">
        
<inertial>
            <mass value="2.637" />
            <origin xyz="0 0 0" />
            <inertia ixx="0.02467" ixy="0" ixz="0" iyy="0.04411" iyz="0" izz="0.02467" />
        </inertial>

        <visual>
            <origin rpy="0 0 0" xyz="0 0 0" />
            <geometry>
                <mesh filename="./meshes/husky/wheel.dae" />
            </geometry>
        </visual>
        <collision>
            <origin rpy="1.570795 0 0" xyz="0 0 0" />
            <geometry>
                <cylinder length="0.1143" radius="0.1651" />
            </geometry>
        </collision>
    </link>
    <gazebo reference="rear_right_wheel_link">
        <mu1 value="1.0" />
        <mu2 value="1.0" />
        <kp value="10000000.0" />
        <kd value="1.0" />
        <fdir1 value="1 0 0" />
    </gazebo>
    <joint name="rear_right_wheel" type="continuous">
        <parent link="base_link" />
        <child link="rear_right_wheel_link" />
        <origin rpy="0 0 0" xyz="-0.256 -0.2854 0.03282" />
        <axis rpy="0 0 0" xyz="0 1 0" />
    </joint>
    <transmission name="rear_right_wheel_trans" type="SimpleTransmission">
        <type>transmission_interface/SimpleTransmission</type>
        <actuator name="rear_right_wheel_motor">
            <mechanicalReduction>1</mechanicalReduction>
        </actuator>
        <joint name="rear_right_wheel">
            <hardwareInterface>hardware_interface/VelocityJointInterface</hardwareInterface>
        </joint>
    </transmission>
    <!-- Spawn Husky chassis -->
    <link name="top_chassis_link">
        <visual>
            <origin rpy="0 0 0" xyz="0 0 0" />
            <geometry>
                <mesh filename="./meshes/husky/top_chassis.dae" />
            </geometry>
        </visual>
    </link>
    <!-- Attach chassis to the robot -->
    <joint name="top_chassis_joint" type="fixed">
        <parent link="base_link" />
        <child link="top_chassis_link" />
    </joint>
    <!-- Spawn user rails -->
    <link name="user_rail_link">
        <visual>
            <geometry>
                <mesh filename="./meshes/husky/user_rail.dae" />
            </geometry>
        </visual>
    </link>
    <!-- Attach user rails to base link -->
    <joint name="user_rail" type="fixed">
        <origin rpy="0 0 0" xyz="0.272 0 0.245" />
        <parent link="base_link" />
        <child link="user_rail_link" />
    </joint>
    <!-- Spawn front bumper link -->
    <link name="front_bumper_link">
        <visual>
            <geometry>
                <mesh filename="./meshes/husky/bumper.dae" />
            </geometry>
        </visual>
    </link>
    <!-- Attach front bumper -->
    <joint name="front_bumper" type="fixed">
        <origin rpy="0 0 0" xyz="0.48 0 0.091" />
        <parent link="base_link" />
        <child link="front_bumper_link" />
    </joint>
    <!-- Spawn rear bumper link -->
    <link name="rear_bumper_link">
        <visual>
            <geometry>
                <mesh filename="./meshes/husky/bumper.dae" />
            </geometry>
        </visual>
    </link>
    <!-- Attach rear bumper -->
    <joint name="rear_bumper" type="fixed">
        <origin rpy="0 0 3.14159" xyz="-0.48 0 0.091" />
        <parent link="base_link" />
        <child link="rear_bumper_link" />
    </joint>
    <link name="top_plate_link">
        <visual>
            <origin rpy="0 0 0" xyz="0 0 0" />
            <geometry>
                <mesh filename="./meshes/husky/top_plate.dae" />
            </geometry>
        </visual>
        <collision>
            <origin rpy="0 0 0" xyz="0 0 0" />
            <geometry>
                <mesh filename="./meshes/husky/top_plate.stl" />
            </geometry>
        </collision>
        
<inertial>
            <mass value="0.1" />
            <inertia ixx="0.03" iyy="0.03" izz="0.03" ixy="0.0" ixz="0.0" iyz="0.0" />
        </inertial>

    </link>
    <!-- Attach top plate -->
    <joint name="top_plate_joint" type="fixed">
        <parent link="base_link" />
        <child link="top_plate_link" />
        <origin rpy="0 0 0" xyz="0.0812 0 0.245" />
    </joint>
    <!-- Top plate front link -->
    <joint name="top_plate_front_joint" type="fixed">
        <parent link="top_plate_link" />
        <child link="top_plate_front_link" />
        <origin rpy="0 0 0" xyz="0.36367 0 0.00639" />
    </joint>
    <!-- Top plate rear link-->
    <joint name="top_plate_rear_joint" type="fixed">
        <parent link="top_plate_link" />
        <child link="top_plate_rear_link" />
        <origin rpy="0 0 0" xyz="-0.36633 0 0.00639" />
    </joint>
    <link name="top_plate_front_link" />
    <link name="top_plate_rear_link" />
    <!-- <xacro:if value="$(arg laser_enabled)">

    <sick_lms1xx_mount prefix="base"/>

    <sick_lms1xx frame="base_laser" topic="scan" robot_namespace="$(arg robot_namespace)"/>

    <joint name="laser_mount_joint" type="fixed">
      <origin xyz="$(arg laser_xyz)" rpy="$(arg laser_rpy)" />
      <parent link="top_plate_link" />
      <child link="velodyne_base_link" />
    </joint>

  </xacro:if> -->
    <material name="Orange">
        <color rgba="0.19607843137254902 0.19607843137254902 0.19607843137254902 1.0" />
    </material>
    <!-- Spawn the sensor arch link -->
    <link name="sensor_arch_mount_link">
        <origin rpy="0 0 0" xyz="0 0 0" />
        <visual>
            <geometry>
                <mesh filename="./meshes/husky/accessories/full_sensor_arch.stl" />
            </geometry>
            <material name="Orange" />
        </visual>
        <collision>
            <origin rpy="0 0 0" xyz="0 0 0" />
            <geometry>
                <mesh filename="./meshes/husky/accessories/full_sensor_arch.stl" />
            </geometry>
        </collision>
        
<inertial>
            <mass value="0.1" />
            <inertia ixx="0.03" iyy="0.03" izz="0.03" ixy="0.0" ixz="0.0" iyz="0.0" />
        </inertial>

    </link>
    <!-- Attach the sensor arch to the top plate -->
    <joint name="sensor_arch_mount" type="fixed">
        <origin rpy="0 0 1.57" xyz="-0.33 0 0.005" />
        <parent link="top_plate_link" />
        <child link="sensor_arch_mount_link" />
    </joint>
    <link name="realsense_mountpoint" />
    <joint name="realsense_mountpoint_joint" type="fixed">
        <origin rpy="0 0 -1.57" xyz="0 -0.037 0.514" />
        <parent link="sensor_arch_mount_link" />
        <child link="realsense_mountpoint" />
    </joint>
    <link name="camera_realsense_lens">
        <visual>
            <!--
          the model's origin is in the middle & it's rotated to lie in
          the optical standard with X left, Y up, and Z forward
        -->
            <origin rpy="1.570796 0 1.570796" xyz="0.0115 0 0.0100" />
            <geometry>
                <!-- Origin of this mesh is the base of the bracket. -->
                <mesh filename="./meshes/realsense/d435.dae" />
            </geometry>
            <material name="white" />
        </visual>
    </link>
    <joint name="camera_realsense_lens_joint" type="fixed">
        <origin rpy="0 0 0" xyz="0 0 0" />
        <parent link="realsense_mountpoint" />
        <child link="camera_realsense_lens" />
    </joint>
    <joint name="camera_realsense_joint" type="fixed">
        <origin rpy="0 0 0" xyz="0.025 0 0" />
        <parent link="camera_realsense_lens" />
        <child link="camera_realsense" />
    </joint>
    <!-- this link is the origin for the camera's data -->
    <link name="camera_realsense" />
    <!--
        The gazebo plugin aligns the depth data with the Z axis, with X=left and Y=up
        ROS expects the depth data along the X axis, with Y=left and Z=up
        This link only exists to give the gazebo plugin the correctly-oriented frame
      -->
    <link name="camera_realsense_gazebo" />
    <joint name="camera_realsense_gazebo_joint" type="fixed">
        <parent link="camera_realsense" />
        <child link="camera_realsense_gazebo" />
        <origin rpy="-1.5707963267948966 0 -1.5707963267948966" xyz="0.0 0 0" />
    </joint>
    <gazebo reference="camera_realsense">
        <turnGravityOff>true</turnGravityOff>
        <sensor name="camera_realsense_depth" type="depth">
            <update_rate>30</update_rate>
            <camera>
                <!-- 75x65 degree FOV for the depth sensor -->
                <horizontal_fov>1.5184351666666667</horizontal_fov>
                <vertical_fov>1.0122901111111111</vertical_fov>
                <image>
                    <width>640</width>
                    <height>480</height>
                    <!-- TODO: check what format the Realsense hardware delivers and set this to match! -->
                    <format>RGB8</format>
                </image>
                <clip>
                    <!-- give the color sensor a maximum range of 50m so that the simulation renders nicely -->
                    <near>0.01</near>
                    <far>50.0</far>
                </clip>
            </camera>
            <plugin filename="libgazebo_ros_openni_kinect.so" name="kinect_controller">
                <baseline>0.2</baseline>
                <alwaysOn>true</alwaysOn>
                <updateRate>30</updateRate>
                <cameraName>realsense</cameraName>
                <imageTopicName>color/image_raw</imageTopicName>
                <cameraInfoTopicName>color/camera_info</cameraInfoTopicName>
                <depthImageTopicName>depth/image_rect_raw</depthImageTopicName>
                <depthImageInfoTopicName>depth/camera_info</depthImageInfoTopicName>
                <pointCloudTopicName>depth/color/points</pointCloudTopicName>
                <frameName>camera_realsense_gazebo</frameName>
                <pointCloudCutoff>0.105</pointCloudCutoff>
                <pointCloudCutoffMax>8.0</pointCloudCutoffMax>
                <distortionK1>0.00000001</distortionK1>
                <distortionK2>0.00000001</distortionK2>
                <distortionK3>0.00000001</distortionK3>
                <distortionT1>0.00000001</distortionT1>
                <distortionT2>0.00000001</distortionT2>
                <CxPrime>0</CxPrime>
                <Cx>0</Cx>
                <Cy>0</Cy>
                <focalLength>0</focalLength>
                <hackBaseline>0</hackBaseline>
            </plugin>
        </sensor>
    </gazebo>
    <!-- <xacro:if value="$(arg laser_enabled)">

    <sick_lms1xx_mount prefix="base"/>

    <sick_lms1xx frame="base_laser" topic="scan" robot_namespace="$(arg robot_namespace)"/>

    <joint name="laser_mount_joint" type="fixed">
      <origin xyz="$(arg laser_xyz)" rpy="$(arg laser_rpy)" />
      <parent link="top_plate_link" />
      <child link="velodyne_base_link" />
    </joint>

  </xacro:if> -->
    <joint name="velodyne_base_mount_joint" type="fixed">
        <origin rpy="0 0 -1.57" xyz="0 0 0.629" />
        <parent link="sensor_arch_mount_link" />
        <child link="velodyne_base_link" />
    </joint>
    <link name="velodyne_base_link">
        
<inertial>
            <mass value="0.83" />
            <origin xyz="0 0 0.03585" />
            <inertia ixx="0.000908059425" ixy="0" ixz="0" iyy="0.000908059425" iyz="0" izz="0.0011049624" />
        </inertial>

        <visual>
            <geometry>
                <mesh filename="./meshes/velodyne/VLP16_base_1.dae" />
            </geometry>
        </visual>
        <visual>
            <geometry>
                <mesh filename="./meshes/velodyne/VLP16_base_2.dae" />
            </geometry>
        </visual>
        <collision>
            <origin rpy="0 0 0" xyz="0 0 0.03585" />
            <geometry>
                <cylinder length="0.0717" radius="0.0516" />
            </geometry>
        </collision>
    </link>
    <joint name="velodyne_base_scan_joint" type="fixed">
        <origin rpy="0 0 0" xyz="0 0 0.0377" />
        <parent link="velodyne_base_link" />
        <child link="velodyne" />
    </joint>
    <link name="velodyne">
        
<inertial>
            <mass value="0.01" />
            <origin xyz="0 0 0" />
            <inertia ixx="1e-7" ixy="0" ixz="0" iyy="1e-7" iyz="0" izz="1e-7" />
        </inertial>

        <visual>
            <origin xyz="0 0 -0.0377" />
            <geometry>
                <mesh filename="./meshes/velodyne/VLP16_scan.dae" />
            </geometry>
        </visual>
    </link>
    <!-- Gazebo requires the velodyne_gazebo_plugins package -->
    <gazebo reference="velodyne">
        <sensor name="velodyne-VLP16" type="ray">
            <pose>0 0 0 0 0 0</pose>
            <visualize>false</visualize>
            <update_rate>10</update_rate>
            <ray>
                <scan>
                    <horizontal>
                        <samples>1875</samples>
                        <resolution>1</resolution>
                        <min_angle>-3.14159</min_angle>
                        <max_angle>3.14159</max_angle>
                    </horizontal>
                    <vertical>
                        <samples>16</samples>
                        <resolution>1</resolution>
                        <min_angle>-0.26179916666666664</min_angle>
                        <max_angle>0.26179916666666664</max_angle>
                    </vertical>
                </scan>
                <range>
                    <min>0.3</min>
                    <max>131.0</max>
                    <resolution>0.001</resolution>
                </range>
                <noise>
                    <type>gaussian</type>
                    <mean>0.0</mean>
                    <stddev>0.0</stddev>
                </noise>
            </ray>
            <plugin filename="libgazebo_ros_velodyne_laser.so" name="gazebo_ros_laser_controller">
                <topicName>/velodyne_points</topicName>
                <frameName>velodyne</frameName>
                <min_range>0.9</min_range>
                <max_range>130.0</max_range>
                <gaussianNoise>0.008</gaussianNoise>
            </plugin>
        </sensor>
    </gazebo>
    <!-- add the intel realsense to the topbar if needed -->
    <gazebo>
        <plugin filename="libgazebo_ros_control.so" name="gazebo_ros_control">
            <robotNamespace>/</robotNamespace>
            <legacyModeNS>true</legacyModeNS>
        </plugin>
    </gazebo>
    <gazebo>
        <plugin filename="libhector_gazebo_ros_imu.so" name="imu_controller">
            <robotNamespace>/</robotNamespace>
            <updateRate>50.0</updateRate>
            <bodyName>base_link</bodyName>
            <topicName>imu/data</topicName>
            <accelDrift>0.005 0.005 0.005</accelDrift>
            <accelGaussianNoise>0.005 0.005 0.005</accelGaussianNoise>
            <rateDrift>0.005 0.005 0.005</rateDrift>
            <rateGaussianNoise>0.005 0.005 0.005</rateGaussianNoise>
            <headingDrift>0.005</headingDrift>
            <headingGaussianNoise>0.005</headingGaussianNoise>
        </plugin>
    </gazebo>
    <gazebo>
        <plugin filename="libhector_gazebo_ros_gps.so" name="gps_controller">
            <robotNamespace>/</robotNamespace>
            <updateRate>40</updateRate>
            <bodyName>base_link</bodyName>
            <frameId>base_link</frameId>
            <topicName>navsat/fix</topicName>
            <velocityTopicName>navsat/vel</velocityTopicName>
            <referenceLatitude>49.9</referenceLatitude>
            <referenceLongitude>8.9</referenceLongitude>
            <referenceHeading>0</referenceHeading>
            <referenceAltitude>0</referenceAltitude>
            <drift>0.0001 0.0001 0.0001</drift>
        </plugin>
    </gazebo>
    <!-- This file is a placeholder which is included by default from
       husky.urdf.xacro. If a robot is being customized and requires
       additional URDF, set the HUSKY_URDF_EXTRAS environment variable
       to the full path of the file you would like included. -->
    <transmission name="trans_ur_arm_shoulder_pan_joint">
        <type>transmission_interface/SimpleTransmission</type>
        <joint name="ur_arm_shoulder_pan_joint">
            <hardwareInterface>hardware_interface/EffortJointInterface</hardwareInterface>
        </joint>
        <actuator name="ur_arm_shoulder_pan_joint_motor">
            <hardwareInterface>hardware_interface/EffortJointInterface</hardwareInterface>
            <mechanicalReduction>1</mechanicalReduction>
        </actuator>
    </transmission>
    <transmission name="trans_ur_arm_shoulder_lift_joint">
        <type>transmission_interface/SimpleTransmission</type>
        <joint name="ur_arm_shoulder_lift_joint">
            <hardwareInterface>hardware_interface/EffortJointInterface</hardwareInterface>
        </joint>
        <actuator name="ur_arm_shoulder_lift_joint_motor">
            <hardwareInterface>hardware_interface/EffortJointInterface</hardwareInterface>
            <mechanicalReduction>1</mechanicalReduction>
        </actuator>
    </transmission>
    <transmission name="trans_ur_arm_elbow_joint">
        <type>transmission_interface/SimpleTransmission</type>
        <joint name="ur_arm_elbow_joint">
            <hardwareInterface>hardware_interface/EffortJointInterface</hardwareInterface>
        </joint>
        <actuator name="ur_arm_elbow_joint_motor">
            <hardwareInterface>hardware_interface/EffortJointInterface</hardwareInterface>
            <mechanicalReduction>1</mechanicalReduction>
        </actuator>
    </transmission>
    <transmission name="trans_ur_arm_wrist_1_joint">
        <type>transmission_interface/SimpleTransmission</type>
        <joint name="ur_arm_wrist_1_joint">
            <hardwareInterface>hardware_interface/EffortJointInterface</hardwareInterface>
        </joint>
        <actuator name="ur_arm_wrist_1_joint_motor">
            <hardwareInterface>hardware_interface/EffortJointInterface</hardwareInterface>
            <mechanicalReduction>1</mechanicalReduction>
        </actuator>
    </transmission>
    <transmission name="trans_ur_arm_wrist_2_joint">
        <type>transmission_interface/SimpleTransmission</type>
        <joint name="ur_arm_wrist_2_joint">
            <hardwareInterface>hardware_interface/EffortJointInterface</hardwareInterface>
        </joint>
        <actuator name="ur_arm_wrist_2_joint_motor">
            <hardwareInterface>hardware_interface/EffortJointInterface</hardwareInterface>
            <mechanicalReduction>1</mechanicalReduction>
        </actuator>
    </transmission>
    <transmission name="trans_ur_arm_wrist_3_joint">
        <type>transmission_interface/SimpleTransmission</type>
        <joint name="ur_arm_wrist_3_joint">
            <hardwareInterface>hardware_interface/EffortJointInterface</hardwareInterface>
        </joint>
        <actuator name="ur_arm_wrist_3_joint_motor">
            <hardwareInterface>hardware_interface/EffortJointInterface</hardwareInterface>
            <mechanicalReduction>1</mechanicalReduction>
        </actuator>
    </transmission>
    <transmission name="trans_robotiq_85_left_knuckle_joint">
        <type>transmission_interface/SimpleTransmission</type>
        <joint name="robotiq_85_left_knuckle_joint">
            <hardwareInterface>hardware_interface/EffortJointInterface</hardwareInterface>
        </joint>
        <actuator name="robotiq_85_left_knuckle_joint_motor">
            <hardwareInterface>hardware_interface/EffortJointInterface</hardwareInterface>
            <mechanicalReduction>1</mechanicalReduction>
        </actuator>
    </transmission>
    <transmission name="trans_robotiq_85_right_knuckle_joint">
        <type>transmission_interface/SimpleTransmission</type>
        <joint name="robotiq_85_right_knuckle_joint">
            <hardwareInterface>hardware_interface/EffortJointInterface</hardwareInterface>
        </joint>
        <actuator name="robotiq_85_right_knuckle_joint_motor">
            <hardwareInterface>hardware_interface/EffortJointInterface</hardwareInterface>
            <mechanicalReduction>1</mechanicalReduction>
        </actuator>
    </transmission>
    <transmission name="trans_robotiq_85_left_inner_knuckle_joint">
        <type>transmission_interface/SimpleTransmission</type>
        <joint name="robotiq_85_left_inner_knuckle_joint">
            <hardwareInterface>hardware_interface/EffortJointInterface</hardwareInterface>
        </joint>
        <actuator name="robotiq_85_left_inner_knuckle_joint_motor">
            <hardwareInterface>hardware_interface/EffortJointInterface</hardwareInterface>
            <mechanicalReduction>1</mechanicalReduction>
        </actuator>
    </transmission>
    <transmission name="trans_robotiq_85_right_inner_knuckle_joint">
        <type>transmission_interface/SimpleTransmission</type>
        <joint name="robotiq_85_right_inner_knuckle_joint">
            <hardwareInterface>hardware_interface/EffortJointInterface</hardwareInterface>
        </joint>
        <actuator name="robotiq_85_right_inner_knuckle_joint_motor">
            <hardwareInterface>hardware_interface/EffortJointInterface</hardwareInterface>
            <mechanicalReduction>1</mechanicalReduction>
        </actuator>
    </transmission>
    <transmission name="trans_robotiq_85_left_finger_tip_joint">
        <type>transmission_interface/SimpleTransmission</type>
        <joint name="robotiq_85_left_finger_tip_joint">
            <hardwareInterface>hardware_interface/EffortJointInterface</hardwareInterface>
        </joint>
        <actuator name="robotiq_85_left_finger_tip_joint_motor">
            <hardwareInterface>hardware_interface/EffortJointInterface</hardwareInterface>
            <mechanicalReduction>1</mechanicalReduction>
        </actuator>
    </transmission>
    <transmission name="trans_robotiq_85_right_finger_tip_joint">
        <type>transmission_interface/SimpleTransmission</type>
        <joint name="robotiq_85_right_finger_tip_joint">
            <hardwareInterface>hardware_interface/EffortJointInterface</hardwareInterface>
        </joint>
        <actuator name="robotiq_85_right_finger_tip_joint_motor">
            <hardwareInterface>hardware_interface/EffortJointInterface</hardwareInterface>
            <mechanicalReduction>1</mechanicalReduction>
        </actuator>
    </transmission>
    <transmission name="trans_front_left_wheel">
        <type>transmission_interface/SimpleTransmission</type>
        <joint name="front_left_wheel">
            <hardwareInterface>hardware_interface/EffortJointInterface</hardwareInterface>
        </joint>
        <actuator name="front_left_wheel_motor">
            <hardwareInterface>hardware_interface/EffortJointInterface</hardwareInterface>
            <mechanicalReduction>1</mechanicalReduction>
        </actuator>
    </transmission>
    <transmission name="trans_front_right_wheel">
        <type>transmission_interface/SimpleTransmission</type>
        <joint name="front_right_wheel">
            <hardwareInterface>hardware_interface/EffortJointInterface</hardwareInterface>
        </joint>
        <actuator name="front_right_wheel_motor">
            <hardwareInterface>hardware_interface/EffortJointInterface</hardwareInterface>
            <mechanicalReduction>1</mechanicalReduction>
        </actuator>
    </transmission>
    <transmission name="trans_rear_left_wheel">
        <type>transmission_interface/SimpleTransmission</type>
        <joint name="rear_left_wheel">
            <hardwareInterface>hardware_interface/EffortJointInterface</hardwareInterface>
        </joint>
        <actuator name="rear_left_wheel_motor">
            <hardwareInterface>hardware_interface/EffortJointInterface</hardwareInterface>
            <mechanicalReduction>1</mechanicalReduction>
        </actuator>
    </transmission>
    <transmission name="trans_rear_right_wheel">
        <type>transmission_interface/SimpleTransmission</type>
        <joint name="rear_right_wheel">
            <hardwareInterface>hardware_interface/EffortJointInterface</hardwareInterface>
        </joint>
        <actuator name="rear_right_wheel_motor">
            <hardwareInterface>hardware_interface/EffortJointInterface</hardwareInterface>
            <mechanicalReduction>1</mechanicalReduction>
        </actuator>
    </transmission>
    <gazebo>
        <plugin name="gazebo_ros_control" filename="libgazebo_ros_control.so">
            <robotNamespace>/</robotNamespace>
        </plugin>
    </gazebo>
</robot>

<transmission name="robotiq_85_left_knuckle_trans">
        <type>transmission_interface/SimpleTransmission</type>
        <joint name="robotiq_85_left_knuckle_joint">
            <hardwareInterface>PositionJointInterface</hardwareInterface>
            <!-- <hardwareInterface>EffortJointInterface</hardwareInterface> -->
        </joint>
        <actuator name="robotiq_85_left_knuckle_motor">
            <mechanicalReduction>1</mechanicalReduction>
            <hardwareInterface>PositionJointInterface</hardwareInterface>
            <!-- <hardwareInterface>EfforJointInterface</hardwareInterface> -->
        </actuator>
    </transmission>
    <!-- Mimic joints -->
    <gazebo>
        <plugin filename="libgazebo_mimic_joint_plugin.so" name="mimic_robotiq_85_1">
            <joint>robotiq_85_left_knuckle_joint</joint>
            <mimicJoint>robotiq_85_right_knuckle_joint</mimicJoint>
        </plugin>
        <plugin filename="libgazebo_mimic_joint_plugin.so" name="mimic_robotiq_85_2">
            <joint>robotiq_85_left_knuckle_joint</joint>
            <mimicJoint>robotiq_85_left_inner_knuckle_joint</mimicJoint>
        </plugin>
        <plugin filename="libgazebo_mimic_joint_plugin.so" name="mimic_robotiq_85_3">
            <joint>robotiq_85_left_knuckle_joint</joint>
            <mimicJoint>robotiq_85_right_inner_knuckle_joint</mimicJoint>
        </plugin>
        <plugin filename="libgazebo_mimic_joint_plugin.so" name="mimic_robotiq_85_4">
            <joint>robotiq_85_left_knuckle_joint</joint>
            <mimicJoint>robotiq_85_left_finger_tip_joint</mimicJoint>
            <multiplier>-1.0</multiplier>
            <offset>0.0</offset>
        </plugin>
        <plugin filename="libgazebo_mimic_joint_plugin.so" name="mimic_robotiq_85_5">
            <joint>robotiq_85_left_knuckle_joint</joint>
            <mimicJoint>robotiq_85_right_finger_tip_joint</mimicJoint>
            <multiplier>-1.0</multiplier>
            <offset>0.0</offset>
        </plugin>
    </gazebo>
    <joint name="ur_arm_ee_fixed_joint" type="fixed">
        <parent link="ur_arm_wrist_3_link" />
        <child link="ur_arm_ee_link" />
        <origin rpy="0.0 0.0 1.5707963267948966" xyz="0.0 0.0823 0.0" />
    </joint>
    <link name="ur_arm_ee_link">
        <collision>
            <geometry>
                <box size="0.01 0.01 0.01" />
            </geometry>
            <origin rpy="0 0 0" xyz="-0.01 0 0" />
        </collision>
        <inertial>
            <mass value="0.1" />
            <inertia ixx="0.03" iyy="0.03" izz="0.03" ixy="0.0" ixz="0.0" iyz="0.0" />
        </inertial>
    </link>
    <transmission name="ur_arm_shoulder_pan_trans">
        <type>transmission_interface/SimpleTransmission</type>
        <joint name="ur_arm_shoulder_pan_joint">
            <hardwareInterface>hardware_interface/PositionJointInterface</hardwareInterface>
        </joint>
        <actuator name="ur_arm_shoulder_pan_motor">
            <mechanicalReduction>1</mechanicalReduction>
        </actuator>
    </transmission>
    <transmission name="ur_arm_shoulder_lift_trans">
        <type>transmission_interface/SimpleTransmission</type>
        <joint name="ur_arm_shoulder_lift_joint">
            <hardwareInterface>hardware_interface/PositionJointInterface</hardwareInterface>
        </joint>
        <actuator name="ur_arm_shoulder_lift_motor">
            <mechanicalReduction>1</mechanicalReduction>
        </actuator>
    </transmission>
    <transmission name="ur_arm_elbow_trans">
        <type>transmission_interface/SimpleTransmission</type>
        <joint name="ur_arm_elbow_joint">
            <hardwareInterface>hardware_interface/PositionJointInterface</hardwareInterface>
        </joint>
        <actuator name="ur_arm_elbow_motor">
            <mechanicalReduction>1</mechanicalReduction>
        </actuator>
    </transmission>
    <transmission name="ur_arm_wrist_1_trans">
        <type>transmission_interface/SimpleTransmission</type>
        <joint name="ur_arm_wrist_1_joint">
            <hardwareInterface>hardware_interface/PositionJointInterface</hardwareInterface>
        </joint>
        <actuator name="ur_arm_wrist_1_motor">
            <mechanicalReduction>1</mechanicalReduction>
        </actuator>
    </transmission>
    <transmission name="ur_arm_wrist_2_trans">
        <type>transmission_interface/SimpleTransmission</type>
        <joint name="ur_arm_wrist_2_joint">
            <hardwareInterface>hardware_interface/PositionJointInterface</hardwareInterface>
        </joint>
        <actuator name="ur_arm_wrist_2_motor">
            <mechanicalReduction>1</mechanicalReduction>
        </actuator>
    </transmission>
    <transmission name="ur_arm_wrist_3_trans">
        <type>transmission_interface/SimpleTransmission</type>
        <joint name="ur_arm_wrist_3_joint">
            <hardwareInterface>hardware_interface/PositionJointInterface</hardwareInterface>
        </joint>
        <actuator name="ur_arm_wrist_3_motor">
            <mechanicalReduction>1</mechanicalReduction>
        </actuator>
    </transmission>
    <gazebo reference="ur_arm_shoulder_link">
        <selfCollide>true</selfCollide>
    </gazebo>
    <gazebo reference="ur_arm_upper_arm_link">
        <selfCollide>true</selfCollide>
    </gazebo>
    <gazebo reference="ur_arm_forearm_link">
        <selfCollide>true</selfCollide>
    </gazebo>
    <gazebo reference="ur_arm_wrist_1_link">
        <selfCollide>true</selfCollide>
    </gazebo>
    <gazebo reference="ur_arm_wrist_3_link">
        <selfCollide>true</selfCollide>
    </gazebo>
    <gazebo reference="ur_arm_wrist_2_link">
        <selfCollide>true</selfCollide>
    </gazebo>
    <gazebo reference="ur_arm_ee_link">
        <selfCollide>true</selfCollide>
    </gazebo>
    <!-- ROS base_link to UR 'Base' Coordinates transform -->
    <link name="ur_arm_base" />
    <joint name="ur_arm_base_link-base_fixed_joint" type="fixed">
        <!-- NOTE: this rotation is only needed as long as base_link itself is
                 not corrected wrt the real robot (ie: rotated over 180
                 degrees)
      -->
        <origin rpy="0 0 -3.141592653589793" xyz="0 0 0" />
        <parent link="ur_arm_base_link" />
        <child link="ur_arm_base" />
    </joint>
    <!-- Frame coincident with all-zeros TCP on UR controller -->
    <link name="ur_arm_tool0" />
    <joint name="ur_arm_wrist_3_link-tool0_fixed_joint" type="fixed">
        <origin rpy="-1.5707963267948966 0 0" xyz="0 0.0823 0" />
        <parent link="ur_arm_wrist_3_link" />
        <child link="ur_arm_tool0" />
    </joint>
    <!-- kinematics_file="${load_yaml('$(arg kinematics_config)')}" -->
    <!-- Base link is the center of the robot's bottom plate -->
    <link name="base_link">
        <visual>
            <origin rpy="0 0 0" xyz="0 0 0" />
            <geometry>
                <mesh filename="./meshes/husky/base_link.dae" />
            </geometry>
        </visual>
        <collision>
            <origin rpy="0 0 0" xyz="0.0 0 0.061875" />
            <geometry>
                <box size="0.9874 0.5709 0.12375" />
            </geometry>
        </collision>
        <collision>
            <origin rpy="0 0 0" xyz="0 0 0.17562499999999998" />
            <geometry>
                <box size="0.7899200000000001 0.5709 0.10375" />
            </geometry>
        </collision>
        <inertial>
            <mass value="0.1" />
            <inertia ixx="0.03" iyy="0.03" izz="0.03" ixy="0.0" ixz="0.0" iyz="0.0" />
        </inertial>
    </link>
    <!-- Base footprint is on the ground under the robot -->
    <link name="base_footprint" />
    <joint name="base_footprint_joint" type="fixed">
        <origin rpy="0 0 0" xyz="0 0 -0.13228" />
        <parent link="base_link" />
        <child link="base_footprint" />
    </joint>
    <!-- Inertial link stores the robot's inertial information -->
    <link name="inertial_link">
        <inertial>
            <mass value="46.034" />
            <origin xyz="-0.00065 -0.085 0.062" />
            <inertia ixx="0.6022" ixy="-0.02364" ixz="-0.1197" iyy="1.7386" iyz="-0.001544" izz="2.0296" />
        </inertial>
    </link>
    <joint name="inertial_joint" type="fixed">
        <origin rpy="0 0 0" xyz="0 0 0" />
        <parent link="base_link" />
        <child link="inertial_link" />
    </joint>
    <!-- IMU Link is the standard mounting position for the UM6 IMU.-->
    <!-- Can be modified with environment variables in /etc/ros/setup.bash -->
    <link name="imu_link" />
    <joint name="imu_joint" type="fixed">
        <origin rpy="0 -1.5708 3.1416" xyz="0.19 0 0.149" />
        <parent link="base_link" />
        <child link="imu_link" />
    </joint>
    <gazebo reference="imu_link" />
    <link name="front_left_wheel_link">
        <inertial>
            <mass value="2.637" />
            <origin xyz="0 0 0" />
            <inertia ixx="0.02467" ixy="0" ixz="0" iyy="0.04411" iyz="0" izz="0.02467" />
        </inertial>
        <visual>
            <origin rpy="0 0 0" xyz="0 0 0" />
            <geometry>
                <mesh filename="./meshes/husky/wheel.dae" />
            </geometry>
        </visual>
        <collision>
            <origin rpy="1.570795 0 0" xyz="0 0 0" />
            <geometry>
                <cylinder length="0.1143" radius="0.1651" />
            </geometry>
        </collision>
    </link>
    <gazebo reference="front_left_wheel_link">
        <mu1 value="1.0" />
        <mu2 value="1.0" />
        <kp value="10000000.0" />
        <kd value="1.0" />
        <fdir1 value="1 0 0" />
    </gazebo>
    <joint name="front_left_wheel" type="continuous">
        <parent link="base_link" />
        <child link="front_left_wheel_link" />
        <origin rpy="0 0 0" xyz="0.256 0.2854 0.03282" />
        <axis rpy="0 0 0" xyz="0 1 0" />
    </joint>
    <transmission name="front_left_wheel_trans" type="SimpleTransmission">
        <type>transmission_interface/SimpleTransmission</type>
        <actuator name="front_left_wheel_motor">
            <mechanicalReduction>1</mechanicalReduction>
        </actuator>
        <joint name="front_left_wheel">
            <hardwareInterface>hardware_interface/VelocityJointInterface</hardwareInterface>
        </joint>
    </transmission>
    <link name="front_right_wheel_link">
        <inertial>
            <mass value="2.637" />
            <origin xyz="0 0 0" />
            <inertia ixx="0.02467" ixy="0" ixz="0" iyy="0.04411" iyz="0" izz="0.02467" />
        </inertial>
        <visual>
            <origin rpy="0 0 0" xyz="0 0 0" />
            <geometry>
                <mesh filename="./meshes/husky/wheel.dae" />
            </geometry>
        </visual>
        <collision>
            <origin rpy="1.570795 0 0" xyz="0 0 0" />
            <geometry>
                <cylinder length="0.1143" radius="0.1651" />
            </geometry>
        </collision>
    </link>
    <gazebo reference="front_right_wheel_link">
        <mu1 value="1.0" />
        <mu2 value="1.0" />
        <kp value="10000000.0" />
        <kd value="1.0" />
        <fdir1 value="1 0 0" />
    </gazebo>
    <joint name="front_right_wheel" type="continuous">
        <parent link="base_link" />
        <child link="front_right_wheel_link" />
        <origin rpy="0 0 0" xyz="0.256 -0.2854 0.03282" />
        <axis rpy="0 0 0" xyz="0 1 0" />
    </joint>
    <transmission name="front_right_wheel_trans" type="SimpleTransmission">
        <type>transmission_interface/SimpleTransmission</type>
        <actuator name="front_right_wheel_motor">
            <mechanicalReduction>1</mechanicalReduction>
        </actuator>
        <joint name="front_right_wheel">
            <hardwareInterface>hardware_interface/VelocityJointInterface</hardwareInterface>
        </joint>
    </transmission>
    <link name="rear_left_wheel_link">
        <inertial>
            <mass value="2.637" />
            <origin xyz="0 0 0" />
            <inertia ixx="0.02467" ixy="0" ixz="0" iyy="0.04411" iyz="0" izz="0.02467" />
        </inertial>
        <visual>
            <origin rpy="0 0 0" xyz="0 0 0" />
            <geometry>
                <mesh filename="./meshes/husky/wheel.dae" />
            </geometry>
        </visual>
        <collision>
            <origin rpy="1.570795 0 0" xyz="0 0 0" />
            <geometry>
                <cylinder length="0.1143" radius="0.1651" />
            </geometry>
        </collision>
    </link>
    <gazebo reference="rear_left_wheel_link">
        <mu1 value="1.0" />
        <mu2 value="1.0" />
        <kp value="10000000.0" />
        <kd value="1.0" />
        <fdir1 value="1 0 0" />
    </gazebo>
    <joint name="rear_left_wheel" type="continuous">
        <parent link="base_link" />
        <child link="rear_left_wheel_link" />
        <origin rpy="0 0 0" xyz="-0.256 0.2854 0.03282" />
        <axis rpy="0 0 0" xyz="0 1 0" />
    </joint>
    <transmission name="rear_left_wheel_trans" type="SimpleTransmission">
        <type>transmission_interface/SimpleTransmission</type>
        <actuator name="rear_left_wheel_motor">
            <mechanicalReduction>1</mechanicalReduction>
        </actuator>
        <joint name="rear_left_wheel">
            <hardwareInterface>hardware_interface/VelocityJointInterface</hardwareInterface>
        </joint>
    </transmission>
    <link name="rear_right_wheel_link">
        <inertial>
            <mass value="2.637" />
            <origin xyz="0 0 0" />
            <inertia ixx="0.02467" ixy="0" ixz="0" iyy="0.04411" iyz="0" izz="0.02467" />
        </inertial>
        <visual>
            <origin rpy="0 0 0" xyz="0 0 0" />
            <geometry>
                <mesh filename="./meshes/husky/wheel.dae" />
            </geometry>
        </visual>
        <collision>
            <origin rpy="1.570795 0 0" xyz="0 0 0" />
            <geometry>
                <cylinder length="0.1143" radius="0.1651" />
            </geometry>
        </collision>
    </link>
    <gazebo reference="rear_right_wheel_link">
        <mu1 value="1.0" />
        <mu2 value="1.0" />
        <kp value="10000000.0" />
        <kd value="1.0" />
        <fdir1 value="1 0 0" />
    </gazebo>
    <joint name="rear_right_wheel" type="continuous">
        <parent link="base_link" />
        <child link="rear_right_wheel_link" />
        <origin rpy="0 0 0" xyz="-0.256 -0.2854 0.03282" />
        <axis rpy="0 0 0" xyz="0 1 0" />
    </joint>
    <transmission name="rear_right_wheel_trans" type="SimpleTransmission">
        <type>transmission_interface/SimpleTransmission</type>
        <actuator name="rear_right_wheel_motor">
            <mechanicalReduction>1</mechanicalReduction>
        </actuator>
        <joint name="rear_right_wheel">
            <hardwareInterface>hardware_interface/VelocityJointInterface</hardwareInterface>
        </joint>
    </transmission>
    <!-- Spawn Husky chassis -->
    <link name="top_chassis_link">
        <visual>
            <origin rpy="0 0 0" xyz="0 0 0" />
            <geometry>
                <mesh filename="./meshes/husky/top_chassis.dae" />
            </geometry>
        </visual>
    </link>
    <!-- Attach chassis to the robot -->
    <joint name="top_chassis_joint" type="fixed">
        <parent link="base_link" />
        <child link="top_chassis_link" />
    </joint>
    <!-- Spawn user rails -->
    <link name="user_rail_link">
        <visual>
            <geometry>
                <mesh filename="./meshes/husky/user_rail.dae" />
            </geometry>
        </visual>
    </link>
    <!-- Attach user rails to base link -->
    <joint name="user_rail" type="fixed">
        <origin rpy="0 0 0" xyz="0.272 0 0.245" />
        <parent link="base_link" />
        <child link="user_rail_link" />
    </joint>
    <!-- Spawn front bumper link -->
    <link name="front_bumper_link">
        <visual>
            <geometry>
                <mesh filename="./meshes/husky/bumper.dae" />
            </geometry>
        </visual>
    </link>
    <!-- Attach front bumper -->
    <joint name="front_bumper" type="fixed">
        <origin rpy="0 0 0" xyz="0.48 0 0.091" />
        <parent link="base_link" />
        <child link="front_bumper_link" />
    </joint>
    <!-- Spawn rear bumper link -->
    <link name="rear_bumper_link">
        <visual>
            <geometry>
                <mesh filename="./meshes/husky/bumper.dae" />
            </geometry>
        </visual>
    </link>
    <!-- Attach rear bumper -->
    <joint name="rear_bumper" type="fixed">
        <origin rpy="0 0 3.14159" xyz="-0.48 0 0.091" />
        <parent link="base_link" />
        <child link="rear_bumper_link" />
    </joint>
    <link name="top_plate_link">
        <visual>
            <origin rpy="0 0 0" xyz="0 0 0" />
            <geometry>
                <mesh filename="./meshes/husky/top_plate.dae" />
            </geometry>
        </visual>
        <collision>
            <origin rpy="0 0 0" xyz="0 0 0" />
            <geometry>
                <mesh filename="./meshes/husky/top_plate.stl" />
            </geometry>
        </collision>
        <inertial>
            <mass value="0.1" />
            <inertia ixx="0.03" iyy="0.03" izz="0.03" ixy="0.0" ixz="0.0" iyz="0.0" />
        </inertial>
    </link>
    <!-- Attach top plate -->
    <joint name="top_plate_joint" type="fixed">
        <parent link="base_link" />
        <child link="top_plate_link" />
        <origin rpy="0 0 0" xyz="0.0812 0 0.245" />
    </joint>
    <!-- Top plate front link -->
    <joint name="top_plate_front_joint" type="fixed">
        <parent link="top_plate_link" />
        <child link="top_plate_front_link" />
        <origin rpy="0 0 0" xyz="0.36367 0 0.00639" />
    </joint>
    <!-- Top plate rear link-->
    <joint name="top_plate_rear_joint" type="fixed">
        <parent link="top_plate_link" />
        <child link="top_plate_rear_link" />
        <origin rpy="0 0 0" xyz="-0.36633 0 0.00639" />
    </joint>
    <link name="top_plate_front_link" />
    <link name="top_plate_rear_link" />
    <!-- <xacro:if value="$(arg laser_enabled)">

    <sick_lms1xx_mount prefix="base"/>

    <sick_lms1xx frame="base_laser" topic="scan" robot_namespace="$(arg robot_namespace)"/>

    <joint name="laser_mount_joint" type="fixed">
      <origin xyz="$(arg laser_xyz)" rpy="$(arg laser_rpy)" />
      <parent link="top_plate_link" />
      <child link="velodyne_base_link" />
    </joint>

  </xacro:if> -->
    <material name="Orange">
        <color rgba="0.19607843137254902 0.19607843137254902 0.19607843137254902 1.0" />
    </material>
    <!-- Spawn the sensor arch link -->
    <link name="sensor_arch_mount_link">
        <origin rpy="0 0 0" xyz="0 0 0" />
        <visual>
            <geometry>
                <mesh filename="./meshes/husky/accessories/full_sensor_arch.stl" />
            </geometry>
            <material name="Orange" />
        </visual>
        <collision>
            <origin rpy="0 0 0" xyz="0 0 0" />
            <geometry>
                <mesh filename="./meshes/husky/accessories/full_sensor_arch.stl" />
            </geometry>
        </collision>
        <inertial>
            <mass value="0.1" />
            <inertia ixx="0.03" iyy="0.03" izz="0.03" ixy="0.0" ixz="0.0" iyz="0.0" />
        </inertial>
    </link>
    <!-- Attach the sensor arch to the top plate -->
    <joint name="sensor_arch_mount" type="fixed">
        <origin rpy="0 0 1.57" xyz="-0.33 0 0.005" />
        <parent link="top_plate_link" />
        <child link="sensor_arch_mount_link" />
    </joint>
    <link name="realsense_mountpoint" />
    <joint name="realsense_mountpoint_joint" type="fixed">
        <origin rpy="0 0 -1.57" xyz="0 -0.037 0.514" />
        <parent link="sensor_arch_mount_link" />
        <child link="realsense_mountpoint" />
    </joint>
    <link name="camera_realsense_lens">
        <visual>
            <!--
          the model's origin is in the middle & it's rotated to lie in
          the optical standard with X left, Y up, and Z forward
        -->
            <origin rpy="1.570796 0 1.570796" xyz="0.0115 0 0.0100" />
            <geometry>
                <!-- Origin of this mesh is the base of the bracket. -->
                <mesh filename="./meshes/realsense/d435.dae" />
            </geometry>
            <material name="white" />
        </visual>
    </link>
    <joint name="camera_realsense_lens_joint" type="fixed">
        <origin rpy="0 0 0" xyz="0 0 0" />
        <parent link="realsense_mountpoint" />
        <child link="camera_realsense_lens" />
    </joint>
    <joint name="camera_realsense_joint" type="fixed">
        <origin rpy="0 0 0" xyz="0.025 0 0" />
        <parent link="camera_realsense_lens" />
        <child link="camera_realsense" />
    </joint>
    <!-- this link is the origin for the camera's data -->
    <link name="camera_realsense" />
    <!--
        The gazebo plugin aligns the depth data with the Z axis, with X=left and Y=up
        ROS expects the depth data along the X axis, with Y=left and Z=up
        This link only exists to give the gazebo plugin the correctly-oriented frame
      -->
    <link name="camera_realsense_gazebo" />
    <joint name="camera_realsense_gazebo_joint" type="fixed">
        <parent link="camera_realsense" />
        <child link="camera_realsense_gazebo" />
        <origin rpy="-1.5707963267948966 0 -1.5707963267948966" xyz="0.0 0 0" />
    </joint>
    <gazebo reference="camera_realsense">
        <turnGravityOff>true</turnGravityOff>
        <sensor name="camera_realsense_depth" type="depth">
            <update_rate>30</update_rate>
            <camera>
                <!-- 75x65 degree FOV for the depth sensor -->
                <horizontal_fov>1.5184351666666667</horizontal_fov>
                <vertical_fov>1.0122901111111111</vertical_fov>
                <image>
                    <width>640</width>
                    <height>480</height>
                    <!-- TODO: check what format the Realsense hardware delivers and set this to match! -->
                    <format>RGB8</format>
                </image>
                <clip>
                    <!-- give the color sensor a maximum range of 50m so that the simulation renders nicely -->
                    <near>0.01</near>
                    <far>50.0</far>
                </clip>
            </camera>
            <plugin filename="libgazebo_ros_openni_kinect.so" name="kinect_controller">
                <baseline>0.2</baseline>
                <alwaysOn>true</alwaysOn>
                <updateRate>30</updateRate>
                <cameraName>realsense</cameraName>
                <imageTopicName>color/image_raw</imageTopicName>
                <cameraInfoTopicName>color/camera_info</cameraInfoTopicName>
                <depthImageTopicName>depth/image_rect_raw</depthImageTopicName>
                <depthImageInfoTopicName>depth/camera_info</depthImageInfoTopicName>
                <pointCloudTopicName>depth/color/points</pointCloudTopicName>
                <frameName>camera_realsense_gazebo</frameName>
                <pointCloudCutoff>0.105</pointCloudCutoff>
                <pointCloudCutoffMax>8.0</pointCloudCutoffMax>
                <distortionK1>0.00000001</distortionK1>
                <distortionK2>0.00000001</distortionK2>
                <distortionK3>0.00000001</distortionK3>
                <distortionT1>0.00000001</distortionT1>
                <distortionT2>0.00000001</distortionT2>
                <CxPrime>0</CxPrime>
                <Cx>0</Cx>
                <Cy>0</Cy>
                <focalLength>0</focalLength>
                <hackBaseline>0</hackBaseline>
            </plugin>
        </sensor>
    </gazebo>
    <!-- <xacro:if value="$(arg laser_enabled)">

    <sick_lms1xx_mount prefix="base"/>

    <sick_lms1xx frame="base_laser" topic="scan" robot_namespace="$(arg robot_namespace)"/>

    <joint name="laser_mount_joint" type="fixed">
      <origin xyz="$(arg laser_xyz)" rpy="$(arg laser_rpy)" />
      <parent link="top_plate_link" />
      <child link="velodyne_base_link" />
    </joint>

  </xacro:if> -->
    <joint name="velodyne_base_mount_joint" type="fixed">
        <origin rpy="0 0 -1.57" xyz="0 0 0.629" />
        <parent link="sensor_arch_mount_link" />
        <child link="velodyne_base_link" />
    </joint>
    <link name="velodyne_base_link">
        <inertial>
            <mass value="0.83" />
            <origin xyz="0 0 0.03585" />
            <inertia ixx="0.000908059425" ixy="0" ixz="0" iyy="0.000908059425" iyz="0" izz="0.0011049624" />
        </inertial>
        <visual>
            <geometry>
                <mesh filename="./meshes/velodyne/VLP16_base_1.dae" />
            </geometry>
        </visual>
        <visual>
            <geometry>
                <mesh filename="./meshes/velodyne/VLP16_base_2.dae" />
            </geometry>
        </visual>
        <collision>
            <origin rpy="0 0 0" xyz="0 0 0.03585" />
            <geometry>
                <cylinder length="0.0717" radius="0.0516" />
            </geometry>
        </collision>
    </link>
    <joint name="velodyne_base_scan_joint" type="fixed">
        <origin rpy="0 0 0" xyz="0 0 0.0377" />
        <parent link="velodyne_base_link" />
        <child link="velodyne" />
    </joint>
    <link name="velodyne">
        <inertial>
            <mass value="0.01" />
            <origin xyz="0 0 0" />
            <inertia ixx="1e-7" ixy="0" ixz="0" iyy="1e-7" iyz="0" izz="1e-7" />
        </inertial>
        <visual>
            <origin xyz="0 0 -0.0377" />
            <geometry>
                <mesh filename="./meshes/velodyne/VLP16_scan.dae" />
            </geometry>
        </visual>
    </link>
    <!-- Gazebo requires the velodyne_gazebo_plugins package -->
    <gazebo reference="velodyne">
        <sensor name="velodyne-VLP16" type="ray">
            <pose>0 0 0 0 0 0</pose>
            <visualize>false</visualize>
            <update_rate>10</update_rate>
            <ray>
                <scan>
                    <horizontal>
                        <samples>1875</samples>
                        <resolution>1</resolution>
                        <min_angle>-3.14159</min_angle>
                        <max_angle>3.14159</max_angle>
                    </horizontal>
                    <vertical>
                        <samples>16</samples>
                        <resolution>1</resolution>
                        <min_angle>-0.26179916666666664</min_angle>
                        <max_angle>0.26179916666666664</max_angle>
                    </vertical>
                </scan>
                <range>
                    <min>0.3</min>
                    <max>131.0</max>
                    <resolution>0.001</resolution>
                </range>
                <noise>
                    <type>gaussian</type>
                    <mean>0.0</mean>
                    <stddev>0.0</stddev>
                </noise>
            </ray>
            <plugin filename="libgazebo_ros_velodyne_laser.so" name="gazebo_ros_laser_controller">
                <topicName>/velodyne_points</topicName>
                <frameName>velodyne</frameName>
                <min_range>0.9</min_range>
                <max_range>130.0</max_range>
                <gaussianNoise>0.008</gaussianNoise>
            </plugin>
        </sensor>
    </gazebo>
    <!-- add the intel realsense to the topbar if needed -->
    <gazebo>
        <plugin filename="libgazebo_ros_control.so" name="gazebo_ros_control">
            <robotNamespace>/</robotNamespace>
            <legacyModeNS>true</legacyModeNS>
        </plugin>
    </gazebo>
    <gazebo>
        <plugin filename="libhector_gazebo_ros_imu.so" name="imu_controller">
            <robotNamespace>/</robotNamespace>
            <updateRate>50.0</updateRate>
            <bodyName>base_link</bodyName>
            <topicName>imu/data</topicName>
            <accelDrift>0.005 0.005 0.005</accelDrift>
            <accelGaussianNoise>0.005 0.005 0.005</accelGaussianNoise>
            <rateDrift>0.005 0.005 0.005</rateDrift>
            <rateGaussianNoise>0.005 0.005 0.005</rateGaussianNoise>
            <headingDrift>0.005</headingDrift>
            <headingGaussianNoise>0.005</headingGaussianNoise>
        </plugin>
    </gazebo>
    <gazebo>
        <plugin filename="libhector_gazebo_ros_gps.so" name="gps_controller">
            <robotNamespace>/</robotNamespace>
            <updateRate>40</updateRate>
            <bodyName>base_link</bodyName>
            <frameId>base_link</frameId>
            <topicName>navsat/fix</topicName>
            <velocityTopicName>navsat/vel</velocityTopicName>
            <referenceLatitude>49.9</referenceLatitude>
            <referenceLongitude>8.9</referenceLongitude>
            <referenceHeading>0</referenceHeading>
            <referenceAltitude>0</referenceAltitude>
            <drift>0.0001 0.0001 0.0001</drift>
        </plugin>
    </gazebo>
    <!-- This file is a placeholder which is included by default from
       husky.urdf.xacro. If a robot is being customized and requires
       additional URDF, set the HUSKY_URDF_EXTRAS environment variable
       to the full path of the file you would like included. -->
    <transmission name="trans_ur_arm_shoulder_pan_joint">
        <type>transmission_interface/SimpleTransmission</type>
        <joint name="ur_arm_shoulder_pan_joint">
            <hardwareInterface>hardware_interface/EffortJointInterface</hardwareInterface>
        </joint>
        <actuator name="ur_arm_shoulder_pan_joint_motor">
            <hardwareInterface>hardware_interface/EffortJointInterface</hardwareInterface>
            <mechanicalReduction>1</mechanicalReduction>
        </actuator>
    </transmission>
    <transmission name="trans_ur_arm_shoulder_lift_joint">
        <type>transmission_interface/SimpleTransmission</type>
        <joint name="ur_arm_shoulder_lift_joint">
            <hardwareInterface>hardware_interface/EffortJointInterface</hardwareInterface>
        </joint>
        <actuator name="ur_arm_shoulder_lift_joint_motor">
            <hardwareInterface>hardware_interface/EffortJointInterface</hardwareInterface>
            <mechanicalReduction>1</mechanicalReduction>
        </actuator>
    </transmission>
    <transmission name="trans_ur_arm_elbow_joint">
        <type>transmission_interface/SimpleTransmission</type>
        <joint name="ur_arm_elbow_joint">
            <hardwareInterface>hardware_interface/EffortJointInterface</hardwareInterface>
        </joint>
        <actuator name="ur_arm_elbow_joint_motor">
            <hardwareInterface>hardware_interface/EffortJointInterface</hardwareInterface>
            <mechanicalReduction>1</mechanicalReduction>
        </actuator>
    </transmission>
    <transmission name="trans_ur_arm_wrist_1_joint">
        <type>transmission_interface/SimpleTransmission</type>
        <joint name="ur_arm_wrist_1_joint">
            <hardwareInterface>hardware_interface/EffortJointInterface</hardwareInterface>
        </joint>
        <actuator name="ur_arm_wrist_1_joint_motor">
            <hardwareInterface>hardware_interface/EffortJointInterface</hardwareInterface>
            <mechanicalReduction>1</mechanicalReduction>
        </actuator>
    </transmission>
    <transmission name="trans_ur_arm_wrist_2_joint">
        <type>transmission_interface/SimpleTransmission</type>
        <joint name="ur_arm_wrist_2_joint">
            <hardwareInterface>hardware_interface/EffortJointInterface</hardwareInterface>
        </joint>
        <actuator name="ur_arm_wrist_2_joint_motor">
            <hardwareInterface>hardware_interface/EffortJointInterface</hardwareInterface>
            <mechanicalReduction>1</mechanicalReduction>
        </actuator>
    </transmission>
    <transmission name="trans_ur_arm_wrist_3_joint">
        <type>transmission_interface/SimpleTransmission</type>
        <joint name="ur_arm_wrist_3_joint">
            <hardwareInterface>hardware_interface/EffortJointInterface</hardwareInterface>
        </joint>
        <actuator name="ur_arm_wrist_3_joint_motor">
            <hardwareInterface>hardware_interface/EffortJointInterface</hardwareInterface>
            <mechanicalReduction>1</mechanicalReduction>
        </actuator>
    </transmission>
    <transmission name="trans_robotiq_85_left_knuckle_joint">
        <type>transmission_interface/SimpleTransmission</type>
        <joint name="robotiq_85_left_knuckle_joint">
            <hardwareInterface>hardware_interface/EffortJointInterface</hardwareInterface>
        </joint>
        <actuator name="robotiq_85_left_knuckle_joint_motor">
            <hardwareInterface>hardware_interface/EffortJointInterface</hardwareInterface>
            <mechanicalReduction>1</mechanicalReduction>
        </actuator>
    </transmission>
    <transmission name="trans_robotiq_85_right_knuckle_joint">
        <type>transmission_interface/SimpleTransmission</type>
        <joint name="robotiq_85_right_knuckle_joint">
            <hardwareInterface>hardware_interface/EffortJointInterface</hardwareInterface>
        </joint>
        <actuator name="robotiq_85_right_knuckle_joint_motor">
            <hardwareInterface>hardware_interface/EffortJointInterface</hardwareInterface>
            <mechanicalReduction>1</mechanicalReduction>
        </actuator>
    </transmission>
    <transmission name="trans_robotiq_85_left_inner_knuckle_joint">
        <type>transmission_interface/SimpleTransmission</type>
        <joint name="robotiq_85_left_inner_knuckle_joint">
            <hardwareInterface>hardware_interface/EffortJointInterface</hardwareInterface>
        </joint>
        <actuator name="robotiq_85_left_inner_knuckle_joint_motor">
            <hardwareInterface>hardware_interface/EffortJointInterface</hardwareInterface>
            <mechanicalReduction>1</mechanicalReduction>
        </actuator>
    </transmission>
    <transmission name="trans_robotiq_85_right_inner_knuckle_joint">
        <type>transmission_interface/SimpleTransmission</type>
        <joint name="robotiq_85_right_inner_knuckle_joint">
            <hardwareInterface>hardware_interface/EffortJointInterface</hardwareInterface>
        </joint>
        <actuator name="robotiq_85_right_inner_knuckle_joint_motor">
            <hardwareInterface>hardware_interface/EffortJointInterface</hardwareInterface>
            <mechanicalReduction>1</mechanicalReduction>
        </actuator>
    </transmission>
    <transmission name="trans_robotiq_85_left_finger_tip_joint">
        <type>transmission_interface/SimpleTransmission</type>
        <joint name="robotiq_85_left_finger_tip_joint">
            <hardwareInterface>hardware_interface/EffortJointInterface</hardwareInterface>
        </joint>
        <actuator name="robotiq_85_left_finger_tip_joint_motor">
            <hardwareInterface>hardware_interface/EffortJointInterface</hardwareInterface>
            <mechanicalReduction>1</mechanicalReduction>
        </actuator>
    </transmission>
    <transmission name="trans_robotiq_85_right_finger_tip_joint">
        <type>transmission_interface/SimpleTransmission</type>
        <joint name="robotiq_85_right_finger_tip_joint">
            <hardwareInterface>hardware_interface/EffortJointInterface</hardwareInterface>
        </joint>
        <actuator name="robotiq_85_right_finger_tip_joint_motor">
            <hardwareInterface>hardware_interface/EffortJointInterface</hardwareInterface>
            <mechanicalReduction>1</mechanicalReduction>
        </actuator>
    </transmission>
    <transmission name="trans_front_left_wheel">
        <type>transmission_interface/SimpleTransmission</type>
        <joint name="front_left_wheel">
            <hardwareInterface>hardware_interface/EffortJointInterface</hardwareInterface>
        </joint>
        <actuator name="front_left_wheel_motor">
            <hardwareInterface>hardware_interface/EffortJointInterface</hardwareInterface>
            <mechanicalReduction>1</mechanicalReduction>
        </actuator>
    </transmission>
    <transmission name="trans_front_right_wheel">
        <type>transmission_interface/SimpleTransmission</type>
        <joint name="front_right_wheel">
            <hardwareInterface>hardware_interface/EffortJointInterface</hardwareInterface>
        </joint>
        <actuator name="front_right_wheel_motor">
            <hardwareInterface>hardware_interface/EffortJointInterface</hardwareInterface>
            <mechanicalReduction>1</mechanicalReduction>
        </actuator>
    </transmission>
    <transmission name="trans_rear_left_wheel">
        <type>transmission_interface/SimpleTransmission</type>
        <joint name="rear_left_wheel">
            <hardwareInterface>hardware_interface/EffortJointInterface</hardwareInterface>
        </joint>
        <actuator name="rear_left_wheel_motor">
            <hardwareInterface>hardware_interface/EffortJointInterface</hardwareInterface>
            <mechanicalReduction>1</mechanicalReduction>
        </actuator>
    </transmission>
    <transmission name="trans_rear_right_wheel">
        <type>transmission_interface/SimpleTransmission</type>
        <joint name="rear_right_wheel">
            <hardwareInterface>hardware_interface/EffortJointInterface</hardwareInterface>
        </joint>
        <actuator name="rear_right_wheel_motor">
            <hardwareInterface>hardware_interface/EffortJointInterface</hardwareInterface>
            <mechanicalReduction>1</mechanicalReduction>
        </actuator>
    </transmission>
    <gazebo>
        <plugin name="gazebo_ros_control" filename="libgazebo_ros_control.so">
            <robotNamespace>/</robotNamespace>
        </plugin>
    </gazebo>
</robot>